Workbook

Sheet Lista de Materiais
A1: 🌱 PROJETO PlantiumAI — Lista de Materiais
A2: Edital Desafio AgroStartup 2026 · Sistema Inteligente de Monitoramento para Micro Estufas Verticais em Containers
A3: # | B3: Componente | C3: Finalidade | D3: Modelo Referência | E3: Qtd | F3: Preço Unit. (R$) | G3: Total (R$) | H3: Observações
A4: MICROCONTROLADORES E PROCESSAMENTO
A5: 1 | B5: ESP32 (Wemos D1) | C5: Leitura dos sensores + Wi-Fi / MQTT | D5: Wemos D1 ESP32 | E5: 2 | F5: 35 | G5: =E5*F5 -> 70 | H5: 2 unidades para redundância e múltiplos nós de sensores | I5: FALSE
A6: 2 | B6: Raspberry Pi 3 Model B | C6: Hub local + controle câmera + envio nuvem | D6: RPi 3B Quad-core 1.2GHz | E6: 1 | F6: 450 | G6: =E6*F6 -> 450 | H6: Processamento local de imagens e hub de comunicação. Fonte 5V/3A inclusa. | I6: FALSE
A7: SENSORES
A8: 3 | B8: Sensor Umidade + Temp. Ar | C8: Monitorar clima interno do container | D8: DHT22/11 | E8: 2 | F8: 30 | G8: =E8*F8 -> 60 | H8: DHT22 recomendado sobre DHT11: maior precisão e estabilidade de longo prazo | I8: TRUE
A9: 4 | B9: Sensor Umidade do Solo | C9: Medir umidade do substrato das mudas | D9: Capacitivo v1.2 | E9: 2 | F9: 25 | G9: =E9*F9 -> 50 | H9: Evitar modelo resistivo FC-28: enferruja em solo úmido | I9: TRUE
A10: 5 | B10: Sensor Temperatura do Solo | C10: Temperatura do substrato (à prova d'água) | D10: DS18B20 | E10: 2 | F10: 20 | G10: =E10*F10 -> 40 | H10: Encapsulamento em aço inox, à prova d'água — ideal para solo | I10: FALSE
A11: 6 | B11: Sensor de Luminosidade | C11: Medir lux disponível para as plantas | D11: BH1750 (I2C) | E11: 1 | F11: 20 | G11: =E11*F11 -> 20 | H11: Protocolo I2C, faixa 1–65535 lux | I11: TRUE
A12: VISÃO COMPUTACIONAL
A13: 7 | B13: Câmera USB IP67 à prova d'água | C13: Captura de imagens para análise da IA | D13: USB 2.0 IP67 | E13: 1 | F13: 120 | G13: =E13*F13 -> 120 | H13: Resistência a umidade e condensação — fundamental para ambiente de estufa | I13: FALSE
A14: ATUADORES E CONTROLE
A15: 8 | B15: Módulo Relé 4 canais | C15: Acionar irrigação, ventilador, iluminação | D15: Relé 5V 4CH | E15: 1 | F15: 30 | G15: =E15*F15 -> 30 | H15: NF = Normalmente Fechada: fecha sem energia (segurança em falha) | I15: TRUE
A16: 9 | B16: Válvula Solenoide 12V ½" | C16: Irrigação automatizada (NF) | D16: Plástico 12V ½" | E16: 1 | F16: 45 | G16: =E16*F16 -> 45 | H16: Tipo NF: fecha sem energia — segurança em caso de falha elétrica | I16: FALSE
A17: 10 | B17: Sensor de Fluxo de Água | C17: Confirmar se irrigação ocorreu | D17: YF-S201 | E17: 1 | F17: 35 | G17: =E17*F17 -> 35 | H17: Cruza dado com sensor de umidade do solo para confirmar irrigação efetiva | I17: TRUE
A18: INFRAESTRUTURA FÍSICA
A19: 11 | B19: Cartão SD 32GB | C19: Armazenamento local de imagens e logs | D19: Classe 10 / A1 | E19: 1 | F19: 30 | G19: =E19*F19 -> 30 | H19: Armazenamento offline: imagens ficam salvas localmente se houver perda de conexão | I19: FALSE
A20: 12 | B20: Fonte 5V 3A + cabos USB | C20: Alimentação do Raspberry Pi e ESP32 | D20: Fonte chaveada 5V/3A | E20: 1 | F20: 40 | G20: =E20*F20 -> 40 | H20: Fonte dedicada evita instabilidade nos sensores por variação de tensão | I20: FALSE
A21: 13 | B21: Cabos, jumpers, resistores | C21: Fiação, montagem e proteção dos circuitos | D21: Kit eletrônica básica | E21: 1 | F21: 60 | G21: =E21*F21 -> 60 | H21: Resistores pull-up para I2C, proteção de GPIO, jumpers macho-macho e fêmea | I21: FALSE
A22: 14 | B22: Roteador 4G LTE | C22: Conectividade remota do container | D22: Roteador 4G industrial | E22: 1 | F22: 350 | G22: =E22*F22 -> 350 | H22: Starlink como alternativa se o local não tiver cobertura 4G (custo muito maior) | I22: TRUE
A23: 15 | B23: MDF | C23: Estrutura do protótipo | D23: Qualquer um serve | E23: 1 | F23: 100 | G23: =E23*F23 -> 100 | H23: Boa sorte | I23: FALSE
A24: TOTAL HARDWARE (1 unidade piloto) | G24: =SUM('Página de Calculo'!A1:A19) -> 955 | H24: Piloto mínimo viável — 1 container
A25: ⚠️ STARLINK (alternativa): antena R$ 2.800 (único) + R$ 250/mês. Usar apenas se local não tiver cobertura 4G.

Sheet Página de Calculo
A1: =IF('Lista de Materiais'!I5 = FALSE, 'Lista de Materiais'!G5, 0) -> 70
A2: =IF('Lista de Materiais'!I6 = FALSE, 'Lista de Materiais'!G6, 0) -> 450
A3: =IF('Lista de Materiais'!I7 = FALSE, 'Lista de Materiais'!G7, 0)
A4: =IF('Lista de Materiais'!I8 = FALSE, 'Lista de Materiais'!G8, 0) -> 0
A5: =IF('Lista de Materiais'!I9 = FALSE, 'Lista de Materiais'!G9, 0) -> 0
A6: =IF('Lista de Materiais'!I10 = FALSE, 'Lista de Materiais'!G10, 0) -> 40
A7: =IF('Lista de Materiais'!I11 = FALSE, 'Lista de Materiais'!G11, 0) -> 0
A8: =IF('Lista de Materiais'!I12 = FALSE, 'Lista de Materiais'!G12, 0)
A9: =IF('Lista de Materiais'!I13 = FALSE, 'Lista de Materiais'!G13, 0) -> 120
A10: =IF('Lista de Materiais'!I14 = FALSE, 'Lista de Materiais'!G14, 0)
A11: =IF('Lista de Materiais'!I15 = FALSE, 'Lista de Materiais'!G15, 0) -> 0
A12: =IF('Lista de Materiais'!I16 = FALSE, 'Lista de Materiais'!G16, 0) -> 45
... A19: =IF('Lista de Materiais'!I23 = FALSE, 'Lista de Materiais'!G23, 0) -> 100

Sheet Lista de Custos
A1: 🌱 PROJETO PlantiumAI — Lista de Custos
A2: Orçamento máximo: R$ 60.000 · Meta de execução: R$ 52.940 · Margem de segurança: R$ 7.060
A3: # | B3: Item de Custo | C3: Descrição | D3: Custo Unit. (R$) | E3: Qtd / Período | F3: Total (R$) | G3: Observações
A4: HARDWARE — INVESTIMENTO ÚNICO (por container piloto)
A5: 1 | B5: Kit Microcontroladores | C5: ESP32 ×2 + Raspberry Pi 3B | D5: 535 | E5: 1 | F5: =D5*E5 -> 535 | G5: Núcleo do sistema embarcado
A6: 2 | B6: Kit Sensores | C6: DHT22, Capacitivo, DS18B20, BH1750 | D6: 170 | E6: 1 | F6: =D6*E6 -> 170 | G6: 4 tipos, 2 unidades cada (redundância)
A7: 3 | B7: Câmera IP67 | C7: Câmera USB à prova d'água | D7: 120 | E7: 1 | F7: =D7*E7 -> 120 | G7: Visão computacional da IA
A8: 4 | B8: Kit Atuadores | C8: Relé 4CH + Válvula + Fluxo YF-S201 | D8: 110 | E8: 1 | F8: =D8*E8 -> 110 | G8: Controle automatizado de irrigação
A9: 5 | B9: Infraestrutura física | C9: SD, fonte, cabos, roteador 4G | D9: 480 | E9: 1 | F9: =D9*E9 -> 480 | G9: Conectividade e alimentação elétrica
A10: Subtotal Hardware (1 container) | F10: =SUM(F5:F9) -> 1415
A12: DESENVOLVIMENTO DE SOFTWARE — INVESTIMENTO ÚNICO
A13: 6 | B13: Backend API + banco de dados | C13: FastAPI, PostgreSQL/TimescaleDB, MQTT | D13: 8250 | E13: 1 | F13: =D13*E13 -> 8250 | G13: ~150h × R$55/h · recebimento de dados dos sensores
A14: 7 | B14: Dashboard web (React) | C14: Interface de monitoramento em tempo real | D14: 4400 | E14: 1 | F14: =D14*E14 -> 4400 | G14: ~80h × R$55/h · gráficos, alertas e histórico
A15: 8 | B15: App mobile (PWA) | C15: Notificações e visualização móvel | D15: 3300 | E15: 1 | F15: =D15*E15 -> 3300 | G15: ~60h × R$55/h · responsivo para agrônomos em campo
A16: 9 | B16: Firmware ESP32 (MQTT) | C16: Leitura e envio dos sensores | D16: 2200 | E16: 1 | F16: =D16*E16 -> 2200 | G16: ~40h × R$55/h
A17: 10 | B17: Agente IA (Claude API) | C17: LangGraph + análise multimodal | D17: 3850 | E17: 1 | F17: =D17*E17 -> 3850 | G17: ~70h × R$55/h · coração do projeto
A18: 11 | B18: Testes, CI/CD, documentação | C18: Qualidade e entrega | D18: 1650 | E18: 1 | F18: =D18*E18 -> 1650 | G18: ~30h × R$55/h
A19: Subtotal Desenvolvimento | F19: =SUM(F13:F18) -> 23650
A21: CUSTOS OPERACIONAIS MENSAIS (a partir do mês 4)
A22: 12 | B22: VPS / Servidor | C22: Railway ou Hetzner — backend + DB | D22: 200 | E22: 1 | F22: =D22*E22 -> 200 | G22: Inclui banco PostgreSQL e armazenamento básico
A23: 13 | B23: Claude API | C23: Haiku 4.5 (alertas) + Sonnet (análise) | D23: 150 | E23: 1 | F23: =D23*E23 -> 150 | G23: Estimativa com prompt caching ativado
A24: 14 | B24: Armazenamento imagens | C24: Backblaze B2 / S3 (~50GB/mês) | D24: 50 | E24: 1 | F24: =D24*E24 -> 50 | G24: Imagens das câmeras de todos os containers
A25: 15 | B25: SIM card 4G | C25: Conectividade do container em campo | D25: 60 | E25: 1 | F25: =D25*E25 -> 60 | G25: Por container — substituível por Starlink
A26: Subtotal Operacional / mês | F26: =SUM(F22:F25) -> 460
A28: MARKETING E DIVULGAÇÃO — INVESTIMENTO ÚNICO
A29: 16 | B29: Identidade visual + landing page | C29: Logo, paleta, copywriting | D29: 1200 | E29: 1 | F29: =D29*E29 -> 1200 | G29: Presença digital profissional
A30: 17 | B30: Vídeo demonstrativo | C30: Gravação na estufa piloto real | D30: 1500 | E30: 1 | F30: =D30*E30 -> 1500 | G30: Principal material de vendas
A31: 18 | B31: Google/Meta Ads | C31: Campanha agro — 4 meses | D31: 2000 | E31: 1 | F31: =D31*E31 -> 2000 | G31: R$ 500/mês por 4 meses
A32: 19 | B32: Evento agro / feira regional | C32: 1 evento presencial | D32: 1200 | E32: 1 | F32: =D32*E32 -> 1200 | G32: Goiás / região Centro-Oeste
A33: 20 | B33: Material impresso | C33: Folder e cartão — 300 unidades | D33: 360 | E33: 1 | F33: =D33*E33 -> 360
A34: Subtotal Marketing | F34: =SUM(F29:F33) -> 6260
A36: LEGAL E ADMINISTRATIVO — INVESTIMENTO ÚNICO
A37: 21 | B37: Abertura empresa + contador | C37: MEI ou LTDA + contabilidade ano 1 | D37: 1200 | E37: 1 | F37: =D37*E37 -> 1200
A38: 22 | B38: Contrato SaaS + NDA | C38: Revisão jurídica dos contratos | D38: 800 | E38: 1 | F38: =D38*E38 -> 800 | G38: Proteção com clientes e parceiros
A39: Subtotal Legal / Admin | F39: =SUM(F37:F38) -> 2000
A41: RESUMO FINANCEIRO
A42: Total Hardware | F42: =F10 -> 1415
A43: Total Desenvolvimento | F43: =F19 -> 23650
A44: Total Operacional (12 meses) | F44: =F26*12 -> 5520
A45: Total Marketing | F45: =F34 -> 6260
...
